<?xml version="1.0" ?>
<!-- =================================================================================== -->
<!-- |    This document was autogenerated by xacro from urdf/panda_xacro/panda_arm_hand.urdf.xacro | -->
<!-- |    EDITING THIS FILE BY HAND IS NOT RECOMMENDED                                 | -->
<!-- =================================================================================== -->
<robot name="panda">
  <!-- END Gazebo adaptation-->
  <!-- END Gazebo adaptation-->
  <!-- Gazebo adaptation: Attach Robot rigidly to the world frame in Gazebo -->
  <link name="world"/>
  <joint name="robot_to_world" type="fixed">
    <parent link="world"/>
    <child link="panda_link0"/>
    <origin rpy="0.0 0.0 0.0" xyz="0.0 0.0 0.0"/>
    <!-- Gazebo adaptation: dampening-->
    <dynamics damping="1.0"/>
    <!-- END Gazebo adaptation-->
  </joint>
  <link name="panda_link0">
    <visual>
      <geometry>
        <mesh filename="package://panda_description/meshes/visual/link0.dae"/>
      </geometry>
    </visual>
    <collision>
      <geometry>
        <mesh filename="package://panda_description/meshes/collision/link0.stl"/>
      </geometry>
    </collision>
    <!-- Gazebo adaptaion: ineria-->
    <inertial>
      <origin rpy="0 0 0" xyz="0 0 0"/>
      <mass value="3.06357"/>
      <inertia ixx="0.3" ixy="0.0" ixz="0.0" iyy="0.3" iyz="0.0" izz="0.3"/>
    </inertial>
    <!-- END Gazebo adaptation-->
  </link>
  <link name="panda_link1">
    <visual>
      <geometry>
        <mesh filename="package://panda_description/meshes/visual/link1.dae"/>
      </geometry>
    </visual>
    <collision>
      <geometry>
        <mesh filename="package://panda_description/meshes/collision/link1.stl"/>
      </geometry>
    </collision>
    <!-- Gazebo adaptaion: ineria-->
    <inertial>
      <origin rpy="0 0 0" xyz="0 0 0"/>
      <mass value="2.34471"/>
      <inertia ixx="0.3" ixy="0.0" ixz="0.0" iyy="0.3" iyz="0.0" izz="0.3"/>
    </inertial>
    <!-- END Gazebo adaptation-->
  </link>
  <joint name="panda_joint1" type="revolute">
    <safety_controller k_position="100.0" k_velocity="40.0" soft_lower_limit="-2.8973" soft_upper_limit="2.8973"/>
    <origin rpy="0 0 0" xyz="0 0 0.333"/>
    <parent link="panda_link0"/>
    <child link="panda_link1"/>
    <axis xyz="0 0 1"/>
    <limit effort="87" lower="-2.8973" upper="2.8973" velocity="2.1750"/>
    <!-- Gazebo adaptation: dampening-->
    <dynamics damping="1.0"/>
    <!-- END Gazebo adaptation-->
  </joint>
  <link name="panda_link2">
    <visual>
      <geometry>
        <mesh filename="package://panda_description/meshes/visual/link2.dae"/>
      </geometry>
    </visual>
    <collision>
      <geometry>
        <mesh filename="package://panda_description/meshes/collision/link2.stl"/>
      </geometry>
    </collision>
    <!-- Gazebo adaptaion: ineria-->
    <inertial>
      <origin rpy="0 0 0" xyz="0 0 0"/>
      <mass value="2.36414"/>
      <inertia ixx="0.3" ixy="0.0" ixz="0.0" iyy="0.3" iyz="0.0" izz="0.3"/>
    </inertial>
    <!-- END Gazebo adaptation-->
  </link>
  <joint name="panda_joint2" type="revolute">
    <safety_controller k_position="100.0" k_velocity="40.0" soft_lower_limit="-1.7628" soft_upper_limit="1.7628"/>
    <origin rpy="-1.5707963267948966 0 0" xyz="0 0 0"/>
    <parent link="panda_link1"/>
    <child link="panda_link2"/>
    <axis xyz="0 0 1"/>
    <limit effort="87" lower="-1.7628" upper="1.7628" velocity="2.1750"/>
    <!-- Gazebo adaptation: dampening-->
    <dynamics damping="1.0"/>
    <!-- END Gazebo adaptation-->
  </joint>
  <link name="panda_link3">
    <visual>
      <geometry>
        <mesh filename="package://panda_description/meshes/visual/link3.dae"/>
      </geometry>
    </visual>
    <collision>
      <geometry>
        <mesh filename="package://panda_description/meshes/collision/link3.stl"/>
      </geometry>
    </collision>
    <!-- Gazebo adaptaion: ineria-->
    <inertial>
      <origin rpy="0 0 0" xyz="0 0 0"/>
      <mass value="2.38050"/>
      <inertia ixx="0.3" ixy="0.0" ixz="0.0" iyy="0.3" iyz="0.0" izz="0.3"/>
    </inertial>
    <!-- END Gazebo adaptation-->
  </link>
  <joint name="panda_joint3" type="revolute">
    <safety_controller k_position="100.0" k_velocity="40.0" soft_lower_limit="-2.8973" soft_upper_limit="2.8973"/>
    <origin rpy="1.5707963267948966 0 0" xyz="0 -0.316 0"/>
    <parent link="panda_link2"/>
    <child link="panda_link3"/>
    <axis xyz="0 0 1"/>
    <limit effort="87" lower="-2.8973" upper="2.8973" velocity="2.1750"/>
    <!-- Gazebo adaptation: dampening-->
    <dynamics damping="1.0"/>
    <!-- END Gazebo adaptation-->
  </joint>
  <link name="panda_link4">
    <visual>
      <geometry>
        <mesh filename="package://panda_description/meshes/visual/link4.dae"/>
      </geometry>
    </visual>
    <collision>
      <geometry>
        <mesh filename="package://panda_description/meshes/collision/link4.stl"/>
      </geometry>
    </collision>
    <!-- Gazebo adaptaion: ineria-->
    <inertial>
      <origin rpy="0 0 0" xyz="0 0 0"/>
      <mass value="2.42754"/>
      <inertia ixx="0.3" ixy="0.0" ixz="0.0" iyy="0.3" iyz="0.0" izz="0.3"/>
    </inertial>
    <!-- END Gazebo adaptation-->
  </link>
  <joint name="panda_joint4" type="revolute">
    <safety_controller k_position="100.0" k_velocity="40.0" soft_lower_limit="-3.0718" soft_upper_limit="-0.0698"/>
    <origin rpy="1.5707963267948966 0 0" xyz="0.0825 0 0"/>
    <parent link="panda_link3"/>
    <child link="panda_link4"/>
    <axis xyz="0 0 1"/>
    <limit effort="87" lower="-3.0718" upper="-0.0698" velocity="2.1750"/>
    <!-- Gazebo adaptation: dampening-->
    <dynamics damping="1.0"/>
    <!-- END Gazebo adaptation-->
  </joint>
  <link name="panda_link5">
    <visual>
      <geometry>
        <mesh filename="package://panda_description/meshes/visual/link5.dae"/>
      </geometry>
    </visual>
    <collision>
      <geometry>
        <mesh filename="package://panda_description/meshes/collision/link5.stl"/>
      </geometry>
    </collision>
    <!-- Gazebo adaptaion: ineria-->
    <inertial>
      <origin rpy="0 0 0" xyz="0 0 0"/>
      <mass value="3.49611"/>
      <inertia ixx="0.3" ixy="0.0" ixz="0.0" iyy="0.3" iyz="0.0" izz="0.3"/>
    </inertial>
    <!-- END Gazebo adaptation-->
  </link>
  <joint name="panda_joint5" type="revolute">
    <safety_controller k_position="100.0" k_velocity="40.0" soft_lower_limit="-2.8973" soft_upper_limit="2.8973"/>
    <origin rpy="-1.5707963267948966 0 0" xyz="-0.0825 0.384 0"/>
    <parent link="panda_link4"/>
    <child link="panda_link5"/>
    <axis xyz="0 0 1"/>
    <limit effort="12" lower="-2.8973" upper="2.8973" velocity="2.6100"/>
    <!-- Gazebo adaptation: dampening-->
    <dynamics damping="1.0"/>
    <!-- END Gazebo adaptation-->
  </joint>
  <link name="panda_link6">
    <visual>
      <geometry>
        <mesh filename="package://panda_description/meshes/visual/link6.dae"/>
      </geometry>
    </visual>
    <collision>
      <geometry>
        <mesh filename="package://panda_description/meshes/collision/link6.stl"/>
      </geometry>
    </collision>
    <!-- Gazebo adaptaion: ineria-->
    <inertial>
      <origin rpy="0 0 0" xyz="0 0 0"/>
      <mass value="1.46736"/>
      <inertia ixx="0.3" ixy="0.0" ixz="0.0" iyy="0.3" iyz="0.0" izz="0.3"/>
    </inertial>
    <!-- END Gazebo adaptation-->
  </link>
  <joint name="panda_joint6" type="revolute">
    <safety_controller k_position="100.0" k_velocity="40.0" soft_lower_limit="-0.0175" soft_upper_limit="3.7525"/>
    <origin rpy="1.5707963267948966 0 0" xyz="0 0 0"/>
    <parent link="panda_link5"/>
    <child link="panda_link6"/>
    <axis xyz="0 0 1"/>
    <limit effort="12" lower="-0.0175" upper="3.7525" velocity="2.6100"/>
    <!-- Gazebo adaptation: dampening-->
    <dynamics damping="1.0"/>
    <!-- END Gazebo adaptation-->
  </joint>
  <link name="panda_link7">
    <visual>
      <geometry>
        <mesh filename="package://panda_description/meshes/visual/link7.dae"/>
      </geometry>
    </visual>
    <collision>
      <geometry>
        <mesh filename="package://panda_description/meshes/collision/link7.stl"/>
      </geometry>
    </collision>
    <!-- Gazebo adaptaion: ineria-->
    <inertial>
      <origin rpy="0 0 0" xyz="0 0 0"/>
      <mass value="0.45606"/>
      <inertia ixx="0.3" ixy="0.0" ixz="0.0" iyy="0.3" iyz="0.0" izz="0.3"/>
    </inertial>
    <!-- END Gazebo adaptation-->
  </link>
  <joint name="panda_joint7" type="revolute">
    <safety_controller k_position="100.0" k_velocity="40.0" soft_lower_limit="-2.8973" soft_upper_limit="2.8973"/>
    <origin rpy="1.5707963267948966 0 0" xyz="0.088 0 0"/>
    <parent link="panda_link6"/>
    <child link="panda_link7"/>
    <axis xyz="0 0 1"/>
    <limit effort="12" lower="-2.8973" upper="2.8973" velocity="2.6100"/>
    <!-- Gazebo adaptation: dampening-->
    <dynamics damping="1.0"/>
    <!-- END Gazebo adaptation-->
  </joint>
  <link name="panda_link8"/>
  <joint name="panda_joint8" type="fixed">
    <origin rpy="0 0 0" xyz="0 0 0.107"/>
    <parent link="panda_link7"/>
    <child link="panda_link8"/>
    <axis xyz="0 0 0"/>
  </joint>
  <joint name="panda_hand_joint" type="fixed">
    <parent link="panda_link8"/>
    <child link="panda_hand"/>
    <origin rpy="0 0 -0.7853981633974483" xyz="0 0 0"/>
    <!-- Gazebo adaptation: dampening-->
    <dynamics damping="1.0"/>
    <!-- END Gazebo adaptation-->
  </joint>
  <link name="panda_hand">
    <visual>
      <geometry>
        <mesh filename="package://panda_description/meshes/visual/hand.dae"/>
      </geometry>
    </visual>
    <collision>
      <geometry>
        <mesh filename="package://panda_description/meshes/collision/hand.stl"/>
      </geometry>
    </collision>
    <!-- Gazebo adaptaion: ineria-->
    <inertial>
      <origin rpy="0 0 0" xyz="0 0 0"/>
      <mass value="0.67893"/>
      <inertia ixx="0.3" ixy="0.0" ixz="0.0" iyy="0.3" iyz="0.0" izz="0.3"/>
    </inertial>
    <!-- END Gazebo adaptation-->
  </link>
  <link name="panda_leftfinger">
    <visual>
      <geometry>
        <mesh filename="package://panda_description/meshes/visual/finger.dae"/>
      </geometry>
    </visual>
    <collision>
      <geometry>
        <mesh filename="package://panda_description/meshes/collision/finger.stl"/>
      </geometry>
    </collision>
    <!-- Gazebo adaptaion: ineria-->
    <inertial>
      <origin rpy="0 0 0" xyz="0 0 0"/>
      <mass value="0.01053"/>
      <inertia ixx="0.3" ixy="0.0" ixz="0.0" iyy="0.3" iyz="0.0" izz="0.3"/>
    </inertial>
    <!-- END Gazebo adaptation-->
  </link>
  <link name="panda_rightfinger">
    <visual>
      <origin rpy="0 0 3.141592653589793" xyz="0 0 0"/>
      <geometry>
        <mesh filename="package://panda_description/meshes/visual/finger.dae"/>
      </geometry>
    </visual>
    <collision>
      <origin rpy="0 0 3.141592653589793" xyz="0 0 0"/>
      <geometry>
        <mesh filename="package://panda_description/meshes/collision/finger.stl"/>
      </geometry>
    </collision>
    <!-- Gazebo adaptaion: ineria-->
    <inertial>
      <origin rpy="0 0 0" xyz="0 0 0"/>
      <mass value="0.01053"/>
      <inertia ixx="0.3" ixy="0.0" ixz="0.0" iyy="0.3" iyz="0.0" izz="0.3"/>
    </inertial>
    <!-- END Gazebo adaptation-->
  </link>
  <joint name="panda_finger_joint1" type="prismatic">
    <parent link="panda_hand"/>
    <child link="panda_leftfinger"/>
    <origin rpy="0 0 0" xyz="0 0 0.0584"/>
    <axis xyz="0 1 0"/>
    <limit effort="20" lower="0.0" upper="0.04" velocity="0.2"/>
    <!-- Gazebo adaptation: dampening-->
    <dynamics damping="1.0"/>
    <!-- END Gazebo adaptation-->
  </joint>
  <joint name="panda_finger_joint2" type="prismatic">
    <parent link="panda_hand"/>
    <child link="panda_rightfinger"/>
    <origin rpy="0 0 0" xyz="0 0 0.0584"/>
    <axis xyz="0 -1 0"/>
    <limit effort="20" lower="0.0" upper="0.04" velocity="0.2"/>
    <!-- Gazebo adaptation: dampening-->
    <dynamics damping="1.0"/>
    <!-- END Gazebo adaptation-->
  </joint>
  <!-- Link0 -->
  <gazebo reference="panda_link0">
    <material>Gazebo/Grey</material>
    <mu1>0.2</mu1>
    <mu2>0.2</mu2>
  </gazebo>
  <!-- Link1 -->
  <gazebo reference="panda_link1">
    <material>Gazebo/White</material>
    <mu1>0.2</mu1>
    <mu2>0.2</mu2>
  </gazebo>
  <!-- Link2 -->
  <gazebo reference="panda_link2">
    <material>Gazebo/White</material>
    <mu1>0.2</mu1>
    <mu2>0.2</mu2>
  </gazebo>
  <!-- Link3 -->
  <gazebo reference="panda_link3">
    <material>Gazebo/White</material>
    <mu1>0.2</mu1>
    <mu2>0.2</mu2>
  </gazebo>
  <!-- Link4 -->
  <gazebo reference="panda_link4">
    <material>Gazebo/White</material>
    <mu1>0.2</mu1>
    <mu2>0.2</mu2>
  </gazebo>
  <!-- Link5 -->
  <gazebo reference="panda_link5">
    <material>Gazebo/White</material>
    <mu1>0.2</mu1>
    <mu2>0.2</mu2>
  </gazebo>
  <!-- Link6 -->
  <gazebo reference="panda_link6">
    <material>Gazebo/White</material>
    <mu1>0.2</mu1>
    <mu2>0.2</mu2>
  </gazebo>
  <!-- Link7 -->
  <gazebo reference="panda_link7">
    <material>Gazebo/Grey</material>
    <mu1>0.2</mu1>
    <mu2>0.2</mu2>
  </gazebo>
  <!-- Link8 -->
  <gazebo reference="panda_link8">
    <material>Gazebo/Grey</material>
    <mu1>0.2</mu1>
    <mu2>0.2</mu2>
  </gazebo>
  <!-- LinkHand -->
  <gazebo reference="panda_hand">
    <material>Gazebo/Grey</material>
    <mu1>0.2</mu1>
    <mu2>0.2</mu2>
  </gazebo>
  <!-- LinkRightFinger -->
  <gazebo reference="panda_rightfinger">
    <material>Gazebo/Grey</material>
    <mu1>0.2</mu1>
    <mu2>0.2</mu2>
  </gazebo>
  <!-- LinkLeftFinger -->
  <gazebo reference="panda_leftfinger">
    <material>Gazebo/Grey</material>
    <mu1>0.2</mu1>
    <mu2>0.2</mu2>
  </gazebo>
  <gazebo>
    <plugin filename="libgazebo_ros_control.so" name="gazebo_ros_control">
      <!--<robotNamespace>/${robot_name}</robotNamespace>-->
      <legacyModeNS>True</legacyModeNS>
    </plugin>
  </gazebo>
  <transmission name="panda_tran_1">
    <type>transmission_interface/SimpleTransmission</type>
    <joint name="panda_joint1">
      <hardwareInterface>hardware_interface/EffortJointInterface</hardwareInterface>
    </joint>
    <actuator name="panda_motor_1">
      <hardwareInterface>hardware_interface/EffortJointInterface</hardwareInterface>
      <mechanicalReduction>1</mechanicalReduction>
    </actuator>
  </transmission>
  <transmission name="panda_tran_2">
    <type>transmission_interface/SimpleTransmission</type>
    <joint name="panda_joint2">
      <hardwareInterface>hardware_interface/EffortJointInterface</hardwareInterface>
    </joint>
    <actuator name="panda_motor_2">
      <hardwareInterface>hardware_interface/EffortJointInterface</hardwareInterface>
      <mechanicalReduction>1</mechanicalReduction>
    </actuator>
  </transmission>
  <transmission name="panda_tran_3">
    <type>transmission_interface/SimpleTransmission</type>
    <joint name="panda_joint3">
      <hardwareInterface>hardware_interface/EffortJointInterface</hardwareInterface>
    </joint>
    <actuator name="panda_motor_3">
      <hardwareInterface>hardware_interface/EffortJointInterface</hardwareInterface>
      <mechanicalReduction>1</mechanicalReduction>
    </actuator>
  </transmission>
  <transmission name="panda_tran_4">
    <type>transmission_interface/SimpleTransmission</type>
    <joint name="panda_joint4">
      <hardwareInterface>hardware_interface/EffortJointInterface</hardwareInterface>
    </joint>
    <actuator name="panda_motor_4">
      <hardwareInterface>hardware_interface/EffortJointInterface</hardwareInterface>
      <mechanicalReduction>1</mechanicalReduction>
    </actuator>
  </transmission>
  <transmission name="panda_tran_5">
    <type>transmission_interface/SimpleTransmission</type>
    <joint name="panda_joint5">
      <hardwareInterface>hardware_interface/EffortJointInterface</hardwareInterface>
    </joint>
    <actuator name="panda_motor_5">
      <hardwareInterface>hardware_interface/EffortJointInterface</hardwareInterface>
      <mechanicalReduction>1</mechanicalReduction>
    </actuator>
  </transmission>
  <transmission name="panda_tran_6">
    <type>transmission_interface/SimpleTransmission</type>
    <joint name="panda_joint6">
      <hardwareInterface>hardware_interface/EffortJointInterface</hardwareInterface>
    </joint>
    <actuator name="panda_motor_6">
      <hardwareInterface>hardware_interface/EffortJointInterface</hardwareInterface>
      <mechanicalReduction>1</mechanicalReduction>
    </actuator>
  </transmission>
  <transmission name="panda_tran_7">
    <type>transmission_interface/SimpleTransmission</type>
    <joint name="panda_joint7">
      <hardwareInterface>hardware_interface/EffortJointInterface</hardwareInterface>
    </joint>
    <actuator name="panda_motor_7">
      <hardwareInterface>hardware_interface/EffortJointInterface</hardwareInterface>
      <mechanicalReduction>1</mechanicalReduction>
    </actuator>
  </transmission>
  <transmission name="panda_leftfinger">
    <type>transmission_interface/SimpleTransmission</type>
    <joint name="panda_finger_joint1">
      <hardwareInterface>hardware_interface/EffortJointInterface</hardwareInterface>
    </joint>
    <actuator name="panda_finger_joint1">
      <hardwareInterface>hardware_interface/EffortJointInterface</hardwareInterface>
      <mechanicalReduction>1</mechanicalReduction>
    </actuator>
  </transmission>
  <transmission name="panda_rightfinger">
    <type>transmission_interface/SimpleTransmission</type>
    <joint name="panda_finger_joint2">
      <hardwareInterface>hardware_interface/EffortJointInterface</hardwareInterface>
    </joint>
    <actuator name="panda_finger_joint2">
      <hardwareInterface>hardware_interface/EffortJointInterface</hardwareInterface>
      <mechanicalReduction>1</mechanicalReduction>
    </actuator>
  </transmission>
</robot>

